<?xml version="1.0" encoding="utf-8"?>
<sdf version='1.9'>
  <model name='rahal_robot'>
    <!-- Base Link -->
    <link name='base_link'>
      <inertial>
        <pose>-0.00133744334022522 6.05357174165988E-07 -0.000970131886296771 0 0 0</pose>
        <mass>1.1439176852714</mass>
        <inertia>
          <ixx>0.446134400302526</ixx>
          <ixy>-2.18000480348373E-05</ixy>
          <ixz>0.0113470100455749</ixz>
          <iyy>0.985173237691484</iyy>
          <iyz>2.52721045797753E-06</iyz>
          <izz>1.332699788346</izz>
        </inertia>
      </inertial>
      <visual name='base_link_visual'>
        <pose>0 0 0 0 0 0</pose>
        <geometry>
          <mesh>
            <scale>1 1 1</scale>
            <uri>package://robot_description/meshes/base_link.STL</uri>
          </mesh>
        </geometry>
        <material>
          <diffuse>0.2 0.2 0.2 1.0</diffuse>
          <ambient>0.2 0.2 0.2 1.0</ambient>
        </material>
      </visual>
      <collision name='base_link_collision'>
        <pose>0 0 0 0 0 0</pose>
        <geometry>
          <mesh>
            <scale>1 1 1</scale>
            <uri>package://robot_description/meshes/base_link.STL</uri>
          </mesh>
        </geometry>
      </collision>
    </link>

    <!-- Front Left Wheel -->
    <link name='front_left_wheel'>
      <pose relative_to='base_link'>0.18279 0.243 -0.014153 0 0 0</pose>  <!-- Adjusted pose -->
      <inertial>
        <pose>-5.92307982660856E-07 0.00883833779366749 -4.20445877558073E-08 0 0 0</pose>
        <mass>0.260404298470105</mass>
        <inertia>
          <ixx>0.000768916188073183</ixx>
          <ixy>-3.91608887242284E-09</ixy>
          <ixz>-1.86122419709981E-08</ixz>
          <iyy>0.00137090251737553</iyy>
          <iyz>-4.72596045124545E-10</iyz>
          <izz>0.000769014346730516</izz>
        </inertia>
      </inertial>
      <visual name='front_left_wheel_visual'>
        <pose>0 0 0 0 0 0</pose>
        <geometry>
          <mesh>
            <scale>1 1 1</scale>
            <uri>package://robot_description/meshes/front_left_wheel.STL</uri>
          </mesh>
        </geometry>
        <material>
          <diffuse>0.0 0.0 0.0 1.0</diffuse>
          <ambient>0.0 0.0 0.0 1.0</ambient>
        </material>
      </visual>
      <collision name='front_left_wheel_collision'>
        <pose>0 0 0 0 0 0</pose>
        <geometry>
          <mesh>
            <scale>1 1 1</scale>
            <uri>package://robot_description/meshes/front_left_wheel.STL</uri>
          </mesh>
        </geometry>
      </collision>
    </link>

    <!-- Front Right Wheel -->
    <link name='front_right_wheel'>
      <pose relative_to='base_link'>0.18279 -0.243 -0.014153 0 0 0</pose>  <!-- Adjusted pose -->
      <inertial>
        <pose>-5.92307982660856E-07 0.00883833779366749 -4.20445877558073E-08 0 0 0</pose>
        <mass>0.260404298470105</mass>
        <inertia>
          <ixx>0.000768916188073183</ixx>
          <ixy>-3.91608887242284E-09</ixy>
          <ixz>-1.86122419709981E-08</ixz>
          <iyy>0.00137090251737553</iyy>
          <iyz>-4.72596045124545E-10</iyz>
          <izz>0.000769014346730516</izz>
        </inertia>
      </inertial>
      <visual name='front_right_wheel_visual'>
        <pose>0 0 0 0 0 0</pose>
        <geometry>
          <mesh>
            <scale>1 1 1</scale>
            <uri>package://robot_description/meshes/front_right_wheel.STL</uri>
          </mesh>
        </geometry>
        <material>
          <diffuse>0.0 0.0 0.0 1.0</diffuse>
          <ambient>0.0 0.0 0.0 1.0</ambient>
        </material>
      </visual>
      <collision name='front_right_wheel_collision'>
        <pose>0 0 0 0 0 0</pose>
        <geometry>
          <mesh>
            <scale>1 1 1</scale>
            <uri>package://robot_description/meshes/front_right_wheel.STL</uri>
          </mesh>
        </geometry>
      </collision>
    </link>

    <!-- Rear Left Wheel -->
    <link name='rear_left_wheel'>
      <pose relative_to='base_link'>-0.17721 -0.24281 -0.014153 0 0 0</pose>  <!-- Adjusted pose -->
      <inertial>
        <pose>-5.92307982660856E-07 0.00883833779366749 -4.20445877558073E-08 0 0 0</pose>
        <mass>0.260404298470105</mass>
        <inertia>
          <ixx>0.000768916188073183</ixx>
          <ixy>-3.91608887242284E-09</ixy>
          <ixz>-1.86122419709981E-08</ixz>
          <iyy>0.00137090251737553</iyy>
          <iyz>-4.72596045124545E-10</iyz>
          <izz>0.000769014346730516</izz>
        </inertia>
      </inertial>
      <visual name='rear_left_wheel_visual'>
        <pose>0 0 0 0 0 0</pose>
        <geometry>
          <mesh>
            <scale>1 1 1</scale>
            <uri>package://robot_description/meshes/rear_left_wheel.STL</uri>
          </mesh>
        </geometry>
        <material>
          <diffuse>0.0 0.0 0.0 1.0</diffuse>
          <ambient>0.0 0.0 0.0 1.0</ambient>
        </material>
      </visual>
      <collision name='rear_left_wheel_collision'>
        <pose>0 0 0 0 0 0</pose>
        <geometry>
          <mesh>
            <scale>1 1 1</scale>
            <uri>package://robot_description/meshes/rear_left_wheel.STL</uri>
          </mesh>
        </geometry>
      </collision>
    </link>

    <!-- Rear Right Wheel -->
    <link name='rear_right_wheel'>
      <pose relative_to='base_link'>-0.17721 0.243 -0.014153 0 0 0</pose>  <!-- Adjusted pose -->
      <inertial>
        <pose>-5.92307982660856E-07 0.00883833779366749 -4.20445877558073E-08 0 0 0</pose>
        <mass>0.260404298470105</mass>
        <inertia>
          <ixx>0.000768916188073183</ixx>
          <ixy>-3.91608887242284E-09</ixy>
          <ixz>-1.86122419709981E-08</ixz>
          <iyy>0.00137090251737553</iyy>
          <iyz>-4.72596045124545E-10</iyz>
          <izz>0.000769014346730516</izz>
        </inertia>
      </inertial>
      <visual name='rear_right_wheel_visual'>
        <pose>0 0 0 0 0 0</pose>
        <geometry>
          <mesh>
            <scale>1 1 1</scale>
            <uri>package://robot_description/meshes/rear_right_wheel.STL</uri>
          </mesh>
        </geometry>
        <material>
          <diffuse>0.0 0.0 0.0 1.0</diffuse>
          <ambient>0.0 0.0 0.0 1.0</ambient>
        </material>
      </visual>
      <collision name='rear_right_wheel_collision'>
        <pose>0 0 0 0 0 0</pose>
        <geometry>
          <mesh>
            <scale>1 1 1</scale>
            <uri>package://robot_description/meshes/rear_right_wheel.STL</uri>
          </mesh>
        </geometry>
      </collision>
    </link>

    <!-- Joints for connecting links -->
    <joint name='front_left_wheel_joint' type='revolute'>
      <parent>base_link</parent>
      <child>front_left_wheel</child>
      <pose>0.18279 0.243 -0.014153 0 0 0</pose>
      <axis>
        <xyz>0 0 1</xyz>
      </axis>
      <limit>
        <effort>10</effort>
        <velocity>10</velocity>
        <lower>-1.57</lower>
        <upper>1.57</upper>
      </limit>
    </joint>

    <joint name='front_right_wheel_joint' type='revolute'>
      <parent>base_link</parent>
      <child>front_right_wheel</child>
      <pose>0.18279 -0.243 -0.014153 0 0 0</pose>
      <axis>
        <xyz>0 0 1</xyz>
      </axis>
      <limit>
        <effort>10</effort>
        <velocity>10</velocity>
        <lower>-1.57</lower>
        <upper>1.57</upper>
      </limit>
    </joint>

    <joint name='rear_left_wheel_joint' type='revolute'>
      <parent>base_link</parent>
      <child>rear_left_wheel</child>
      <pose>-0.17721 0.243 -0.014153 0 0 0</pose>
      <axis>
        <xyz>0 0 1</xyz>
      </axis>
      <limit>
        <effort>10</effort>
        <velocity>10</velocity>
        <lower>-1.57</lower>
        <upper>1.57</upper>
      </limit>
    </joint>

    <joint name='rear_right_wheel_joint' type='revolute'>
      <parent>base_link</parent>
      <child>rear_right_wheel</child>
      <pose>-0.17721 -0.24281 -0.014153 0 0 0</pose>
      <axis>
        <xyz>0 0 1</xyz>
      </axis>
      <limit>
        <effort>10</effort>
        <velocity>10</velocity>
        <lower>-1.57</lower>
        <upper>1.57</upper>
      </limit>
    </joint>



<link name='lidar_link'>
      <inertial>
        <pose>0.23529 0 0.085747 0 0 0</pose>
        <mass>0.2</mass>
        <inertia>
          <ixx>0.0002</ixx>
          <ixy>0</ixy>
          <ixz>0</ixz>
          <iyy>0.0002</iyy>
          <iyz>0</iyz>
          <izz>0.0002</izz>
        </inertia>
      </inertial>
      <visual name='base_link_fixed_joint_lump__laser_link_visual_2'>
        <pose>0.23529 0 0.085747 0 0 0</pose>
        <geometry>
          <mesh>
            <scale>0.001 0.001 0.001</scale>
            <uri>package://robot_description/meshes/lidar_link.STL</uri>
          </mesh>
        </geometry>
        <material>
          <diffuse>0.0 0.0 0.0 1</diffuse>
          <ambient>0.0 0.0 0.0 1</ambient>
        </material>
      </visual>
      <collision name='base_link_fixed_joint_lump__laser_link_collision_2'>
        <pose>0.00174 0.00064 0.0959 0 0 0</pose>
        <geometry>
          <mesh>
            <scale>0.001 0.001 0.001</scale>
            <uri>package://robot_description/meshes/lidar_link.STL</uri>
          </mesh>
        </geometry>
      </collision>
      <sensor name="lidar" type="gpu_lidar">
        <pose>0.23529 0 0.085747 0 0 0</pose>
        <lidar>
          <scan>
            <horizontal>
              <samples>400</samples>
              <resolution>1</resolution>
              <min_angle>-1.5707</min_angle>
              <max_angle>1.5707</max_angle>
            </horizontal>
          </scan>
          <range>
            <min>0.15</min>
            <max>25</max>
            <resolution>0.01</resolution>
          </range>
        </lidar>
        <frame_id>lidar_link</frame_id>
        <topic>scan</topic>
        <alwaysOn>1</alwaysOn>
        <visualize>true</visualize>
        <update_rate>10</update_rate>
      </sensor>
    </link>

    <joint name='base_to_lidar_joint' type='fixed'>
      <pose>0.23529 0 0.085747 0 0 0</pose>
      <parent>base_link</parent>
      <child>lidar_link</child>
    </joint>

    

  </model>
</sdf>
