<?xml version="1.0" encoding="utf-8"?>
<sdf version='1.7'>
  <model name='rahal_robot'>
    <!-- Base Link -->
    <link name='base_link'>
      <inertial>
        <pose>-0.00133744334022522 6.05357174165988E-07 -0.000970131886296771 0 0 0</pose>
        <mass>1.1439176852714</mass>
        <inertia>
          <ixx>0.446134400302526</ixx>
          <ixy>-2.18000480348373E-05</ixy>
          <ixz>0.0113470100455749</ixz>
          <iyy>0.985173237691484</iyy>
          <iyz>2.52721045797753E-06</iyz>
          <izz>1.332699788346</izz>
        </inertia>
      </inertial>
      <visual name='base_link_visual'>
        <pose>0 0 0 0 0 0</pose>
        <geometry>
          <mesh>
            <scale>1 1 1</scale>
            <uri>package://robot_description/meshes/base_link.STL</uri>
          </mesh>
        </geometry>
        <material>
          <diffuse>0.2 0.2 0.2 1.0</diffuse>
          <ambient>0.2 0.2 0.2 1.0</ambient>
        </material>
      </visual>
      <collision name='base_link_collision'>
        <pose>0 0 0 0 0 0</pose>
        <geometry>
          <mesh>
            <scale>1 1 1</scale>
            <uri>package://robot_description/meshes/base_link.STL</uri>
          </mesh>
        </geometry>
      </collision>
    </link>

    <!-- Front Left Wheel -->
    <link name='front_left_wheel'>
      <pose relative_to='base_link'>0 0 0 0 0 0</pose>  <!-- Adjusted pose -->
      <inertial>
        <pose>0 0 0 0 0 0</pose>
        <mass>0.260404298470105</mass>
        <inertia>
          <ixx>0.000768916188073183</ixx>
          <ixy>-3.91608887242284E-09</ixy>
          <ixz>-1.86122419709981E-08</ixz>
          <iyy>0.00137090251737553</iyy>
          <iyz>-4.72596045124545E-10</iyz>
          <izz>0.000769014346730516</izz>
        </inertia>
      </inertial>
      <visual name='front_left_wheel_visual'>
        <pose>0.18279 0.243 -0.014153 0 0 0</pose>
        <geometry>
          <mesh>
            <scale>1 1 1</scale>
            <uri>package://robot_description/meshes/front_left_wheel.STL</uri>
          </mesh>
        </geometry>
        <material>
          <diffuse>0.0 0.0 0.0 1.0</diffuse>
          <ambient>0.0 0.0 0.0 1.0</ambient>
        </material>
      </visual>
      <collision name='front_left_wheel_collision'>
        <pose>0 0 0 0 0 0</pose>
        <geometry>
          <mesh>
            <scale>1 1 1</scale>
            <uri>package://robot_description/meshes/front_left_wheel.STL</uri>
          </mesh>
            <surface>
          <!-- This friction pamareter don't contain reliable data!! -->
          <friction>
            <ode>
              <mu>100000.0</mu>
              <mu2>100000.0</mu2>
              <fdir1>0 0 0</fdir1>
              <slip1>0.0</slip1>
              <slip2>0.0</slip2>
            </ode>
          </friction>
          <contact>
            <ode>
              <soft_cfm>0</soft_cfm>
              <soft_erp>0.2</soft_erp>
              <kp>1e+5</kp>
              <kd>1</kd>
              <max_vel>0.01</max_vel>
              <min_depth>0.001</min_depth>
            </ode>
          </contact>
        </surface>
        </geometry>
      </collision>
    </link>

    <!-- Front Right Wheel -->
    <link name='front_right_wheel'>
      <pose relative_to='base_link'>0 0 0 0 0 0</pose>  <!-- Adjusted pose -->
      <inertial>
        <pose>0 0 0 0 0 0</pose>
        <mass>0.260404298470105</mass>
        <inertia>
          <ixx>0.000768916188073183</ixx>
          <ixy>-3.91608887242284E-09</ixy>
          <ixz>-1.86122419709981E-08</ixz>
          <iyy>0.00137090251737553</iyy>
          <iyz>-4.72596045124545E-10</iyz>
          <izz>0.000769014346730516</izz>
        </inertia>
      </inertial>
      <visual name='front_right_wheel_visual'>
        <pose>0.18279 -0.243 -0.014153 0 0 0</pose>
        <geometry>
          <mesh>
            <scale>1 1 1</scale>
            <uri>package://robot_description/meshes/front_right_wheel.STL</uri>
          </mesh>
        </geometry>
        <material>
          <diffuse>0.0 0.0 0.0 1.0</diffuse>
          <ambient>0.0 0.0 0.0 1.0</ambient>
        </material>
      </visual>
      <collision name='front_right_wheel_collision'>
        <pose>0 0 0 0 0 0</pose>
        <geometry>
          <mesh>
            <scale>1 1 1</scale>
            <uri>package://robot_description/meshes/front_right_wheel.STL</uri>
          </mesh>
            <surface>
          <!-- This friction pamareter don't contain reliable data!! -->
          <friction>
            <ode>
              <mu>100000.0</mu>
              <mu2>100000.0</mu2>
              <fdir1>0 0 0</fdir1>
              <slip1>0.0</slip1>
              <slip2>0.0</slip2>
            </ode>
          </friction>
          <contact>
            <ode>
              <soft_cfm>0</soft_cfm>
              <soft_erp>0.2</soft_erp>
              <kp>1e+5</kp>
              <kd>1</kd>
              <max_vel>0.01</max_vel>
              <min_depth>0.001</min_depth>
            </ode>
          </contact>
        </surface>
        </geometry>
      </collision>
    </link>

    <!-- Rear Left Wheel -->
    <link name='rear_left_wheel'>
      <pose relative_to='base_link'>0 0 0 0 0 0</pose>  <!-- Adjusted pose -->
      <inertial>
        <pose>0 0 0 0 0 0</pose>
        <mass>0.260404298470105</mass>
        <inertia>
          <ixx>0.000768916188073183</ixx>
          <ixy>-3.91608887242284E-09</ixy>
          <ixz>-1.86122419709981E-08</ixz>
          <iyy>0.00137090251737553</iyy>
          <iyz>-4.72596045124545E-10</iyz>
          <izz>0.000769014346730516</izz>
        </inertia>
      </inertial>
      <visual name='rear_left_wheel_visual'>
        <pose>-0.17721 0.243 -0.014153 0 0 0</pose>
        <geometry>
          <mesh>
            <scale>1 1 1</scale>
            <uri>package://robot_description/meshes/rear_left_wheel.STL</uri>
          </mesh>
        </geometry>
        <material>
          <diffuse>0.0 0.0 0.0 1.0</diffuse>
          <ambient>0.0 0.0 0.0 1.0</ambient>
        </material>
      </visual>
      <collision name='rear_left_wheel_collision'>
        <pose>0 0 0 0 0 0</pose>
        <geometry>
          <mesh>
            <scale>1 1 1</scale>
            <uri>package://robot_description/meshes/rear_left_wheel.STL</uri>
          </mesh>
            <surface>
          <!-- This friction pamareter don't contain reliable data!! -->
          <friction>
            <ode>
              <mu>100000.0</mu>
              <mu2>100000.0</mu2>
              <fdir1>0 0 0</fdir1>
              <slip1>0.0</slip1>
              <slip2>0.0</slip2>
            </ode>
          </friction>
          <contact>
            <ode>
              <soft_cfm>0</soft_cfm>
              <soft_erp>0.2</soft_erp>
              <kp>1e+5</kp>
              <kd>1</kd>
              <max_vel>0.01</max_vel>
              <min_depth>0.001</min_depth>
            </ode>
          </contact>
        </surface>
        </geometry>
      </collision>
    </link>

    <!-- Rear Right Wheel -->
    <link name='rear_right_wheel'>
      <pose relative_to='base_link'>0 0 0 0 0 0</pose>  <!-- Adjusted pose -->
      <inertial>
        <pose>0 0 0 0 0 0</pose>
        <mass>0.260404298470105</mass>
        <inertia>
          <ixx>0.000768916188073183</ixx>
          <ixy>-3.91608887242284E-09</ixy>
          <ixz>-1.86122419709981E-08</ixz>
          <iyy>0.00137090251737553</iyy>
          <iyz>-4.72596045124545E-10</iyz>
          <izz>0.000769014346730516</izz>
        </inertia>
      </inertial>
      <visual name='rear_right_wheel_visual'>
        <pose>-0.17721 -0.24281 -0.014153 0 0 0</pose>
        <geometry>
          <mesh>
            <scale>1 1 1</scale>
            <uri>package://robot_description/meshes/rear_right_wheel.STL</uri>
          </mesh>
          
        </geometry>

        <material>
          <diffuse>0.0 0.0 0.0 1.0</diffuse>
          <ambient>0.0 0.0 0.0 1.0</ambient>
        </material>
      </visual>
      <collision name='rear_right_wheel_collision'>
        <pose>0 0 0 0 0 0</pose>
        <geometry>
          <mesh>
            <scale>1 1 1</scale>
            <uri>package://robot_description/meshes/rear_right_wheel.STL</uri>
          </mesh>
            <surface>
          <!-- This friction pamareter don't contain reliable data!! -->
          <friction>
            <ode>
              <mu>100000.0</mu>
              <mu2>100000.0</mu2>
              <fdir1>0 0 0</fdir1>
              <slip1>0.0</slip1>
              <slip2>0.0</slip2>
            </ode>
          </friction>
          <contact>
            <ode>
              <soft_cfm>0</soft_cfm>
              <soft_erp>0.2</soft_erp>
              <kp>1e+5</kp>
              <kd>1</kd>
              <max_vel>0.01</max_vel>
              <min_depth>0.001</min_depth>
            </ode>
          </contact>
        </surface>
        </geometry>
      </collision>
    </link>

    <!-- Joints for connecting links -->
    <joint name='front_left_wheel_joint' type='revolute'>
      <parent>base_link</parent>
      <child>front_left_wheel</child>
      <pose>0.18279 0.243 -0.014153 0 0 0</pose>
      <axis>
        <xyz>0 1 0</xyz>
      </axis>
      <limit>
        <effort>10</effort>
        <velocity>10</velocity>
     
      </limit>
    </joint>

    <joint name='front_right_wheel_joint' type='revolute'>
      <parent>base_link</parent>
      <child>front_right_wheel</child>
      <pose>0.18279 -0.243 -0.014153 0 0 0</pose>
      <axis>
        <xyz>0 1 0</xyz>
      </axis>
      <limit>
        <effort>10</effort>
        <velocity>10</velocity>

      </limit>
    </joint>

    <joint name='rear_left_wheel_joint' type='revolute'>
      <parent>base_link</parent>
      <child>rear_left_wheel</child>
      <pose>-0.17721 0.243 -0.014153 0 0 0</pose>
      <axis>
        <xyz>0 1 0</xyz>
      </axis>
      <limit>
        <effort>10</effort>
        <velocity>10</velocity>
  
      </limit>
    </joint>

    <joint name='rear_right_wheel_joint' type='revolute'>
      <parent>base_link</parent>
      <child>rear_right_wheel</child>
      <pose>-0.17721 -0.24281 -0.014153 0 0 0</pose>
      <axis>
        <xyz>0 1 0</xyz>
      </axis>
      <limit>
        <effort>10</effort>
        <velocity>10</velocity>

      </limit>
    </joint>


<link name='lidar_link'>
      <pose relative_to='base_link'>0.23529 0 0.085747 0 0 0</pose>  <!-- Adjusted pose -->

      <inertial>
        <pose>0 0 0 0 0 0</pose>
        <mass>0.2</mass>
        <inertia>
          <ixx>0.0002</ixx>
          <ixy>0</ixy>
          <ixz>0</ixz>
          <iyy>0.0002</iyy>
          <iyz>0</iyz>
          <izz>0.0002</izz>
        </inertia>
      </inertial>
      <visual name='base_link_fixed_joint_lump__laser_link_visual_2'>
        <pose>0 0 0 0 0 0</pose>
        <geometry>
          <mesh>
            <scale>1 1 1</scale>
            <uri>package://robot_description/meshes/lidar_link.STL</uri>
          </mesh>
        </geometry>
        <material>
          <diffuse>0.0 0.0 0.0 1</diffuse>
          <ambient>0.0 0.0 0.0 1</ambient>
        </material>
      </visual>
      <collision name='base_link_fixed_joint_lump__laser_link_collision_2'>
        <pose>0 0 0  0 0 0</pose>
        <geometry>
          <mesh>
            <scale>1 1 1</scale>
            <uri>package://robot_description/meshes/lidar_link.STL</uri>
          </mesh>
        </geometry>
      </collision>
 <sensor name="lidar_link" type="gpu_lidar">
        <gz_frame_id>lidar_link</gz_frame_id>
        <topic>scan</topic>
        <update_rate>30</update_rate>
        <lidar>
          <scan>
            <horizontal>
              <samples>2800</samples>
              <resolution>1</resolution>
              <min_angle>-1.5707</min_angle>
              <max_angle>1.5707</max_angle>
            </horizontal>
            <vertical>
              <samples>1</samples>
              <resolution>0.1</resolution>
              <min_angle>0.0</min_angle>
              <max_angle>0.0</max_angle>
            </vertical>
          </scan>
          <range>
            <min>0.15</min>
            <max>25</max>
            <resolution>0.01</resolution>
          </range>
          <frame_id>/lidar_link</frame_id>
        </lidar>
           <always_on>1</always_on>
            <visualize>true</visualize>
      </sensor>
    </link>

    <joint name='base_to_lidar_joint' type='fixed'>
      <pose>0.23529 0 0.085747 0 0 0</pose>
      <parent>base_link</parent>
      <child>lidar_link</child>
    </joint>





    <link name='camera_link'>
      <inertial>
        <pose>0.1284 0 0.07444 0 0 0</pose>
        <mass>0.15</mass>
        <inertia>
        <ixx>0.00015</ixx>
        <ixy>0</ixy>
        <ixz>0</ixz>
        <iyy>0.00015</iyy>
        <iyz>0</iyz>
        <izz>0.00015</izz>
        </inertia>
      </inertial>
      <visual name='base_link_fixed_joint_lump__camera_link_visual_1'>
        <pose>0.1284 0 0.07444 1.57 0 1.57</pose>
        <geometry>
          <mesh>
            <scale>1 1 1</scale>
            <uri>package://robot_description/meshes/realsenseD435.dae</uri>
          </mesh>
        </geometry>
        <material>
          <diffuse>0 0 1 1</diffuse>
          <ambient>0 0 1 1</ambient>
        </material>
      </visual>
      <collision name='base_link_fixed_joint_lump__camera_link_collision_1'>
        <pose>0.1284 0 0.07444 1.57 0 1.57</pose>
        <geometry>
          <mesh>
            <scale>1 1 1</scale>
            <uri>package://robot_description/meshes/realsenseD435.dae</uri>
          </mesh>
        </geometry>
      </collision>

      <sensor name="camera" type="camera">
        <pose>0.1284 0 0.07444 0 0 0</pose>
        <camera>
          <horizontal_fov>1.367</horizontal_fov>
          <image>
            <width>640</width>
            <height>480</height>
          </image>
          <clip>
            <near>0.05</near>
            <far>200</far>
          </clip>
        </camera>
        <!-- Set frame ID appropriately, typically 'camera_link' -->
        <gz_frame_id>camera_link</gz_frame_id>
        <always_on>1</always_on>
        <update_rate>10</update_rate>
        <visualize>1</visualize>
        <topic>rgb_image</topic>
      </sensor>
    </link>
    <joint name='base_to_camera_joint' type='fixed'>
      <pose>0.1284 0 0.07444 1.57 0 1.57</pose>
      <parent>base_link</parent>
      <child>camera_link</child>
    </joint>

 <plugin filename="gz-sim-diff-drive-system" name="gz::sim::systems::DiffDrive">
    <left_joint>front_left_wheel_joint</left_joint>
    <left_joint>rear_left_wheel_joint</left_joint>
    <right_joint>front_right_wheel_joint</right_joint>
    <right_joint>rear_right_wheel_joint</right_joint>
    <wheel_separation>0.45</wheel_separation> 
    <wheel_radius>0.09</wheel_radius> 
    <child_frame_id>base_link</child_frame_id>  <!-- Changed from base_footprint to base_link -->
    <tf_topic>/tf</tf_topic> 
    <topic>/cmd_vel</topic>
</plugin>

   

<plugin filename="gz-sim-joint-state-publisher-system"
        name="gz::sim::systems::JointStatePublisher">
    <joint_name>front_left_wheel_joint</joint_name>
    <joint_name>front_right_wheel_joint</joint_name>
    <joint_name>rear_left_wheel_joint</joint_name>
    <joint_name>rear_right_wheel_joint</joint_name>
</plugin>
  </model>
</sdf>
